Workbook

Sheet Estimate
B1: EXTERIOR PAINTING ESTIMATE
B2: Ottawa, Ontario • Residential Exterior • All amounts in CAD
B4: Client name: | G4: Project address:
B5: Phone / email: | G5: Estimate date:
B6: Estimate #: | G6: Prepared by:
B7: Job notes: | G7: Valid until:
B9: 1. SIDING / WALL SURFACES
B10: Item / surface | C10: Qty | D10: Unit | E10: Coats | F10: Rate | G10: Labour hrs | H10: Labour $ | I10: Materials $ | J10: Line total | K10: Notes
B11: Wood siding | D11: sf | E11: 2 | F11: ='Rates & Settings'!$B$16 -> 120 | G11: =IF(F11=0,0,C11/F11) -> 0 | H11: =G11*'Rates & Settings'!$B$6 -> 0 | I11: =IF('Rates & Settings'!$B$9=0,0,(C11*1*E11/'Rates & Settings'!$B$9)*'Rates & Settings'!$B$51*(1+'Rates & Settings'!$B$12)) -> 0 | J11: =H11+I11 -> 0
B12: Vinyl siding | C12: 0 | D12: sf | E12: 2 | F12: ='Rates & Settings'!$B$17 -> 150 | G12: =IF(F12=0,0,C12/F12) -> 0 | H12: =G12*'Rates & Settings'!$B$6 -> 0 | I12: =IF('Rates & Settings'!$B$9=0,0,(C12*1*E12/'Rates & Settings'!$B$9)*'Rates & Settings'!$B$51*(1+'Rates & Settings'!$B$12)) -> 0 | J12: =H12+I12 -> 0
B13: Aluminum siding | C13: 0 | D13: sf | E13: 2 | F13: ='Rates & Settings'!$B$18 -> 150 | G13: =IF(F13=0,0,C13/F13) -> 0 | H13: =G13*'Rates & Settings'!$B$6 -> 0 | I13: =IF('Rates & Settings'!$B$9=0,0,(C13*1*E13/'Rates & Settings'!$B$9)*'Rates & Settings'!$B$51*(1+'Rates & Settings'!$B$12)) -> 0 | J13: =H13+I13 -> 0
B14: Stucco / parging | C14: 0 | D14: sf | E14: 2 | F14: ='Rates & Settings'!$B$19 -> 100 | G14: =IF(F14=0,0,C14/F14) -> 0 | H14: =G14*'Rates & Settings'!$B$6 -> 0 | I14: =IF('Rates & Settings'!$B$9=0,0,(C14*1*E14/'Rates & Settings'!$B$9)*'Rates & Settings'!$B$51*(1+'Rates & Settings'!$B$12)) -> 0 | J14: =H14+I14 -> 0
B15: Brick (paint) | C15: 0 | D15: sf | E15: 2 | F15: ='Rates & Settings'!$B$20 -> 100 | G15: =IF(F15=0,0,C15/F15) -> 0 | H15: =G15*'Rates & Settings'!$B$6 -> 0 | I15: =IF('Rates & Settings'!$B$9=0,0,(C15*1*E15/'Rates & Settings'!$B$9)*'Rates & Settings'!$B$51*(1+'Rates & Settings'!$B$12)) -> 0 | J15: =H15+I15 -> 0
B16: Cement board (Hardie) | C16: 0 | D16: sf | E16: 2 | F16: ='Rates & Settings'!$B$21 -> 100 | G16: =IF(F16=0,0,C16/F16) -> 0 | H16: =G16*'Rates & Settings'!$B$6 -> 0 | I16: =IF('Rates & Settings'!$B$9=0,0,(C16*1*E16/'Rates & Settings'!$B$9)*'Rates & Settings'!$B$51*(1+'Rates & Settings'!$B$12)) -> 0 | J16: =H16+I16 -> 0
B17: Other / custom | C17: 0 | D17: sf | E17: 2 | F17: ='Rates & Settings'!$B$22 -> 200 | G17: =IF(F17=0,0,C17/F17) -> 0 | H17: =G17*'Rates & Settings'!$B$6 -> 0 | I17: =IF('Rates & Settings'!$B$9=0,0,(C17*1*E17/'Rates & Settings'!$B$9)*'Rates & Settings'!$B$51*(1+'Rates & Settings'!$B$12)) -> 0 | J17: =H17+I17 -> 0
B18: Siding — prep work
B19: Masking / taping | C19: 0 | D19: hr | F19: ='Rates & Settings'!$B$59 -> 40 | G19: =C19 -> 0 | J19: =C19*F19 -> 0
B20: Sanding | C20: 0 | D20: hr | F20: ='Rates & Settings'!$B$60 -> 40 | G20: =C20 -> 0 | J20: =C20*F20 -> 0
B21: Other prep (caulk, repair, etc.) | C21: 0 | D21: hr | F21: ='Rates & Settings'!$B$61 -> 45 | G21: =C21 -> 0 | J21: =C21*F21 -> 0
B22: Siding subtotal → | J22: =SUM(J11,J12,J13,J14,J15,J16,J17,J19,J20,J21) -> 0
B24: 2. TRIM / SOFFIT / FASCIA / EAVES
B25: Item / surface | C25: Qty | D25: Unit | E25: Coats | F25: Rate | G25: Labour hrs | H25: Labour $ | I25: Materials $ | J25: Line total | K25: Notes
B26: Window / door trim | C26: 0 | D26: lf | E26: 2 | F26: ='Rates & Settings'!$B$26 -> 40 | G26: =IF(F26=0,0,C26/F26) -> 0 | H26: =G26*'Rates & Settings'!$B$6 -> 0 | I26: =IF('Rates & Settings'!$B$9=0,0,(C26*0.7*E26/'Rates & Settings'!$B$9)*'Rates & Settings'!$B$51*(1+'Rates & Settings'!$B$12)) -> 0 | J26: =H26+I26 -> 0
B27: Soffits | C27: 120 | D27: lf | E27: 2 | F27: ='Rates & Settings'!$B$27 -> 60 | G27: =IF(F27=0,0,C27/F27) -> 2 | H27: =G27*'Rates & Settings'!$B$6 -> 80 | I27: =IF('Rates & Settings'!$B$9=0,0,(C27*0.7*E27/'Rates & Settings'!$B$9)*'Rates & Settings'!$B$51*(1+'Rates & Settings'!$B$12)) -> 46.92 | J27: =H27+I27 -> 126.92
B28: Fascia board | C28: 120 | D28: lf | E28: 2 | F28: ='Rates & Settings'!$B$28 -> 50 | G28: =IF(F28=0,0,C28/F28) -> 2.4 | H28: =G28*'Rates & Settings'!$B$6 -> 96 | I28: =IF('Rates & Settings'!$B$9=0,0,(C28*0.7*E28/'Rates & Settings'!$B$9)*'Rates & Settings'!$B$51*(1+'Rates & Settings'!$B$12)) -> 46.92 | J28: =H28+I28 -> 142.92
B29: Eavestroughs (gutters) | C29: 0 | D29: lf | E29: 2 | F29: ='Rates & Settings'!$B$29 -> 55 | G29: =IF(F29=0,0,C29/F29) -> 0 | H29: =G29*'Rates & Settings'!$B$6 -> 0 | I29: =IF('Rates & Settings'!$B$9=0,0,(C29*0.7*E29/'Rates & Settings'!$B$9)*'Rates & Settings'!$B$51*(1+'Rates & Settings'!$B$12)) -> 0 | J29: =H29+I29 -> 0
B30: Gable / corner trim | C30: 0 | D30: lf | E30: 2 | F30: ='Rates & Settings'!$B$30 -> 45 | G30: =IF(F30=0,0,C30/F30) -> 0 | H30: =G30*'Rates & Settings'!$B$6 -> 0 | I30: =IF('Rates & Settings'!$B$9=0,0,(C30*0.7*E30/'Rates & Settings'!$B$9)*'Rates & Settings'!$B$51*(1+'Rates & Settings'!$B$12)) -> 0 | J30: =H30+I30 -> 0
B31: Other linear trim | C31: 0 | D31: lf | E31: 2 | F31: ='Rates & Settings'!$B$31 -> 40 | G31: =IF(F31=0,0,C31/F31) -> 0 | H31: =G31*'Rates & Settings'!$B$6 -> 0 | I31: =IF('Rates & Settings'!$B$9=0,0,(C31*0.7*E31/'Rates & Settings'!$B$9)*'Rates & Settings'!$B$51*(1+'Rates & Settings'!$B$12)) -> 0 | J31: =H31+I31 -> 0
B32: Trim — prep work
B33: Masking / taping | C33: 4 | D33: hr | F33: ='Rates & Settings'!$B$59 -> 40 | G33: =C33 -> 4 | J33: =C33*F33 -> 160
B34: Sanding | C34: 0 | D34: hr | F34: ='Rates & Settings'!$B$60 -> 40 | G34: =C34 -> 0 | J34: =C34*F34 -> 0
B35: Other prep (caulk, repair, etc.) | C35: 0 | D35: hr | F35: ='Rates & Settings'!$B$61 -> 45 | G35: =C35 -> 0 | J35: =C35*F35 -> 0
B36: Trim / soffit / fascia subtotal → | J36: =SUM(J26,J27,J28,J29,J30,J31,J33,J34,J35) -> 429.84
B38: 3. DOORS & WINDOWS
B39: Item | C39: Quantity | D39: Unit | E39: Coats | F39: Hrs / unit | G39: Labour hrs | H39: Labour $ | I39: Materials $ | J39: Line total | K39: Notes
B40: Entry door (front/back) | C40: 0 | D40: each | E40: 2 | F40: ='Rates & Settings'!$B$35 -> 2.5 | G40: =C40*F40 -> 0 | H40: =G40*'Rates & Settings'!$B$6 -> 0 | I40: =IF('Rates & Settings'!$B$9=0,0,(C40*40*E40/'Rates & Settings'!$B$9)*'Rates & Settings'!$B$51*(1+'Rates & Settings'!$B$12)) -> 0 | J40: =H40+I40 -> 0
B41: Garage door — single | C41: 0 | D41: each | E41: 2 | F41: ='Rates & Settings'!$B$36 -> 4 | G41: =C41*F41 -> 0 | H41: =G41*'Rates & Settings'!$B$6 -> 0 | I41: =IF('Rates & Settings'!$B$9=0,0,(C41*60*E41/'Rates & Settings'!$B$9)*'Rates & Settings'!$B$51*(1+'Rates & Settings'!$B$12)) -> 0 | J41: =H41+I41 -> 0
B42: Garage door — double | C42: 0 | D42: each | E42: 2 | F42: ='Rates & Settings'!$B$37 -> 6 | G42: =C42*F42 -> 0 | H42: =G42*'Rates & Settings'!$B$6 -> 0 | I42: =IF('Rates & Settings'!$B$9=0,0,(C42*120*E42/'Rates & Settings'!$B$9)*'Rates & Settings'!$B$51*(1+'Rates & Settings'!$B$12)) -> 0 | J42: =H42+I42 -> 0
B43: Window frame (avg) | C43: 5 | D43: each | E43: 2 | F43: ='Rates & Settings'!$B$38 -> 0.75 | G43: =C43*F43 -> 3.75 | H43: =G43*'Rates & Settings'!$B$6 -> 150 | I43: =IF('Rates & Settings'!$B$9=0,0,(C43*15*E43/'Rates & Settings'!$B$9)*'Rates & Settings'!$B$51*(1+'Rates & Settings'!$B$12)) -> 41.892857 | J43: =H43+I43 -> 191.89286
B44: Shutter pair | C44: 0 | D44: each | E44: 2 | F44: ='Rates & Settings'!$B$39 -> 0.5 | G44: =C44*F44 -> 0 | H44: =G44*'Rates & Settings'!$B$6 -> 0 | I44: =IF('Rates & Settings'!$B$9=0,0,(C44*20*E44/'Rates & Settings'!$B$9)*'Rates & Settings'!$B$51*(1+'Rates & Settings'!$B$12)) -> 0 | J44: =H44+I44 -> 0
...

Sheet Rates & Settings
A1: Rates & Settings — Edit any value to update all estimates
A2: All cells in BLUE are editable. Estimates auto-update from these values.
A4: GLOBAL SETTINGS
A5: Item | B5: Value | C5: Unit | D5: Notes
A6: Labour rate (cost) | B6: 40 | C6: $/hr | D6: Internal labour cost per painter-hour
A7: Markup (overhead + profit) | B7: 1 | C7: % | D7: Applied to labour + materials
A8: HST | B8: 0.13 | C8: % | D8: Ontario harmonized sales tax
A9: Paint coverage (1 coat) | B9: 350 | C9: sf/gal | D9: Typical exterior latex on smooth surface
A10: Stain coverage (1 coat) | B10: 200 | C10: sf/gal | D10: Typical semi-transparent deck stain
A11: Primer coverage (1 coat) | B11: 300 | C11: sf/gal | D11: When required for bare wood / stains
A12: Sundries (% of paint cost) | B12: 0.15 | C12: % | D12: Tape, drop cloths, brushes, etc.
A14: PRODUCTION RATES — SIDING / WALL SURFACES
A15: Item | B15: Value | C15: Unit | D15: Notes
A16: Wood siding (clapboard, T1-11) | B16: 120 | C16: sf/hr | D16: Brush/roll or spray with backroll
A17: Vinyl siding | B17: 150 | C17: sf/hr | D17: Faster — already finished surface, requires bonding primer
A18: Aluminum siding | B18: 150 | C18: sf/hr | D18: Similar to vinyl; light scuff sand
A19: Stucco / parging | B19: 100 | C19: sf/hr | D19: Roll with thick nap or spray
A20: Brick (paint) | B20: 100 | C20: sf/hr | D20: Pre-prime, two coats elastomeric
A21: Cement board (Hardie) | B21: 100 | C21: sf/hr | D21: Spray with backroll
A22: Other / custom | B22: 200 | C22: sf/hr | D22: Edit rate as needed
A24: PRODUCTION RATES — TRIM / SOFFIT / FASCIA / EAVES
A25: Item | B25: Value | C25: Unit | D25: Notes
A26: Window / door trim | B26: 40 | C26: lf/hr | D26: Includes cutting in
A27: Soffits | B27: 60 | C27: lf/hr | D27: Above eye-level, ladder work
A28: Fascia board | B28: 50 | C28: lf/hr | D28: Ladder/scaffold required
A29: Eavestroughs (gutters) | B29: 55 | C29: lf/hr | D29: Light scuff, exterior latex
A30: Gable / corner trim | B30: 45 | C30: lf/hr | D30: Includes detail work
A31: Other linear trim | B31: 40 | C31: lf/hr | D31: Edit rate as needed
A33: DOORS & WINDOWS — HOURS PER UNIT
A34: Item | B34: Value | C34: Unit | D34: Notes
A35: Entry door (front/back) | B35: 2.5 | C35: hr/each | D35: Frame + slab, includes prep
A36: Garage door — single (8x7) | B36: 4 | C36: hr/each | D36: Two coats, ladder work
A37: Garage door — double (16x7) | B37: 6 | C37: hr/each | D37: Two coats, ladder work
A38: Window frame (avg) | B38: 0.75 | C38: hr/each | D38: Exterior frame only, exterior latex
A39: Shutter pair | B39: 0.5 | C39: hr/pair | D39: Remove, paint, rehang
A40: Other door/window unit | B40: 1.5 | C40: hr/each | D40: Edit as needed
A42: DECKS / RAILINGS — PRODUCTION RATES
A43: Item | B43: Value | C43: Unit | D43: Notes
A44: Deck floor (stain) | B44: 100 | C44: sf/hr | D44: Roll + brush detail; uses stain
A45: Deck railing (stain) | B45: 25 | C45: lf/hr | D45: Spindles add time
...
